<?xml version="1.0" ?>
<!-- =================================================================================== -->
<!-- |    This document was autogenerated by xacro from ../xacro/robot.xacro           | -->
<!-- |    EDITING THIS FILE BY HAND IS NOT RECOMMENDED                                 | -->
<!-- =================================================================================== -->
<robot name="cheetah">

    <link name="ground"></link>
    <joint name="ground_t_floating" type="revolute">
    <origin rpy="0 0 0" xyz="0 0 0.45"/>
    <parent link="ground"/>
    <child link="trunk"/>
    <limit effort="20" lower="-0.872664625997" upper="1.0471975512" velocity="10.6"/>
    </joint>

  <link name="trunk">
    <visual>
      <origin rpy="0 0 0" xyz="0 0 0"/>
      <geometry>
        <mesh filename="../meshes/trunk.STL" scale="1 1 1"/>
      </geometry>
      <material name="white_gray"/>
    </visual>
    <collision>
      <origin rpy="0 0 0" xyz="0 0 0"/>
      <geometry>
        <!-- <mesh filename="../meshes/trunk.STL" scale="1 1 1"/> -->
        <box size="0.3 0.2 0.093"/>
      </geometry>
    </collision>
    <inertial>
      <origin rpy="0 0 0" xyz="0.0 0.0 0.0"/>
      <mass value="3.3"/>
      <inertia ixx="0.011253" ixy="0" ixz="0.0" iyy="0.036203" iyz="-0.0" izz="0.042673"/>
    </inertial>
  </link>

  <joint name="RL_hip_joint" type="revolute">
    <origin rpy="0 0 0" xyz="-0.196 0.049664 0"/>
    <parent link="trunk"/>
    <child link="RL_hip"/>
    <axis xyz="1 0 0"/>
    <dynamics damping="0" friction="0"/>
    <limit effort="20" lower="-0.872664625997" upper="1.0471975512" velocity="10.6"/>
  </joint>

  <link name="RL_hip">
    <visual>
      <origin rpy="-3.14159265359 0 0" xyz="0 0 0"/>
      <geometry>
        <mesh filename="../meshes/hip.STL" scale="1 1 1"/>
      </geometry>
      <material name="gold"/>
    </visual>
    
    <inertial>
      <origin rpy="0 0 0" xyz="0.0 -0.036 0.0"/>
      <mass value="0.57"/>
      <inertia ixx="0.0007148275" ixy="0.0" ixz="0.0" iyy="0.0007955775" iyz="0.0" izz="0.00068875"/>
    </inertial>
  </link>
  
  <joint name="RL_thigh_joint" type="revolute">
    <origin rpy="3.14159265359 3.14159265359 0" xyz="0 0.077476 0"/>
    <parent link="RL_hip"/>
    <child link="RL_thigh"/>
    <axis xyz="0 1 0"/>
    <dynamics damping="0" friction="0"/>
    <limit effort="20" lower="-0.523598775598" upper="3.92699081699" velocity="10.6"/>
  </joint>

  <link name="RL_thigh">
    <visual>
      <origin rpy="3.14159265359 3.14159265359 0" xyz="0 0 0"/>
      <geometry>
        <mesh filename="../meshes/thigh.STL" scale="1 1 1"/>
      </geometry>
      <material name="white_blue"/>
    </visual>
    <inertial>
      <origin rpy="0 0 0" xyz="0.0 -0.016 -0.11"/>
      <mass value="0.634"/>
      <inertia ixx="0.00261820866667" ixy="0.0" ixz="0.0" iyy="0.00265482216667" iyz="0.0" izz="0.000158764166667"/>
    </inertial>
  </link>


  <joint name="RL_calf_joint" type="revolute">
    <origin rpy="0 0 0" xyz="0 0.009 -0.2115"/>
    <parent link="RL_thigh"/>
    <child link="RL_calf"/>
    <axis xyz="0 1 0"/>
    <dynamics damping="0" friction="0"/>
    <!-- <limit effort="${calf_torque_max}" velocity="${calf_velocity_max}" lower="${calf_min*PI/180.0}" upper="${calf_max*PI/180.0}"/> -->
    <limit effort="20" lower="-3.14159265359" upper="3.14159265359" velocity="10.6"/>
  </joint>
  <link name="RL_calf">
    <visual>
      <origin rpy="0 0 0" xyz="0.0 0.0 0.0"/>
      <geometry>
        <mesh filename="../meshes/calf.STL" scale="1 1 1"/>
      </geometry>
      <material name="white_blue"/>
    </visual>
    <collision>
      <origin rpy="0 0 0" xyz="0.0 0.0 -0.1"/>
      <geometry>
        <box size="0.016 0.016 0.2"/>
        <!-- <mesh filename="../meshes/calf.STL" scale="1 1 1"/> -->
      </geometry>
    </collision>
    <inertial>
      <origin rpy="0 0 0" xyz="0.0 0.0 0.0"/>
      <mass value="0.064"/>
      <inertia ixx="0.000214698666667" ixy="0.0" ixz="0.0" iyy="0.000214698666667" iyz="0.0" izz="2.73066666667e-06"/>
    </inertial>
  </link>
  <!-- //////////////////////foot//////////////////// -->
  <joint name="RL_foot_fixed" type="fixed">
    <origin rpy="0 0 0" xyz="0 0.01 -0.21"/>
    <parent link="RL_calf"/>
    <child link="RL_foot"/>
  </joint>
  <link name="RL_foot">
    <visual>
      <origin rpy="0 0 0" xyz="0 0 0"/>
      <geometry>
        <mesh filename="../meshes/foot.STL" scale="1 1 1"/>
      </geometry>
      <material name="white_black"/>
    </visual>
    <collision>
      <origin rpy="0 0 0" xyz="0 0.0 0.025"/>
      <geometry>
        <!-- <mesh filename="../meshes/foot.STL" scale="1 1 1"/> -->
        <sphere radius="0.025"/>
      </geometry>
    </collision>
    <inertial>
      <origin rpy="0 0 0" xyz="0.0 0.0 0"/>
      <mass value="0.15"/>
      <inertia ixx="4.2135e-05" ixy="0.0" ixz="0.0" iyy="4.2135e-05" iyz="0.0" izz="4.2135e-05"/>
    </inertial>
  </link>
  <!-- //////////////////////hip//////////////////// -->
  <joint name="FL_hip_joint" type="revolute">
    <!-- <joint name="${name}_hip_joint" type="continuous"> -->
    <origin rpy="0 -3.14159265359 0" xyz="0.196 0.049664 0"/>
    <parent link="trunk"/>
    <child link="FL_hip"/>
    <axis xyz="1 0 0"/>
    <dynamics damping="0" friction="0"/>
    <limit effort="20" lower="-0.872664625997" upper="1.0471975512" velocity="10.6"/>
  </joint>
  <link name="FL_hip">
    <visual>
      <origin rpy="3.14159265359 3.14159265359 0" xyz="0 0 0"/>
      <geometry>
        <mesh filename="../meshes/hip.STL" scale="1 1 1"/>
      </geometry>
      <material name="gold"/>
    </visual>
    <collision>
      <!-- <origin rpy="${PI/2.0} 0 0" xyz="0 0 0"/> -->
      <!-- <xacro:if value="${(mirror_dae == True) and (front_hind_dae == True)}">
                    <origin rpy="0 0 0" xyz="0 0 0"/>
                </xacro:if>
                <xacro:if value="${(mirror_dae == False) and (front_hind_dae == True)}">
                    <origin rpy="${PI} 0 0" xyz="0 0 0"/>
                </xacro:if>
                <xacro:if value="${(mirror_dae == True) and (front_hind_dae == False)}">
                    <origin rpy="0 ${PI} 0" xyz="0 0 0"/>
                </xacro:if>
                <xacro:if value="${(mirror_dae == False) and (front_hind_dae == False)}">
                    <origin rpy="${PI} ${PI} 0" xyz="0 0 0"/>
                </xacro:if> -->
      <geometry>
        <!-- <mesh filename="../meshes/hip.STL" scale="1 1 1"/> -->
        <box size="0.09 0.08 0.093"/>
      </geometry>
    </collision>
    <inertial>
      <origin rpy="0 0 0" xyz="-0.0 -0.036 0.0"/>
      <mass value="0.57"/>
      <inertia ixx="0.0007148275" ixy="0.0" ixz="0.0" iyy="0.0007955775" iyz="0.0" izz="0.00068875"/>
    </inertial>
  </link>
  <!-- //////////////////////thigh//////////////////// -->
  <joint name="FL_thigh_joint" type="revolute">
    <!-- <joint name="${name}_thigh_joint" type="continuous"> -->
    <origin rpy="3.14159265359 0 0" xyz="0 0.077476 0"/>
    <parent link="FL_hip"/>
    <child link="FL_thigh"/>
    <axis xyz="0 1 0"/>
    <dynamics damping="0" friction="0"/>
    <limit effort="20" lower="-0.523598775598" upper="3.92699081699" velocity="10.6"/>
  </joint>
  <link name="FL_thigh">
    <visual>
      <origin rpy="3.14159265359 3.14159265359 0" xyz="0 0 0"/>
      <geometry>
        <mesh filename="../meshes/thigh.STL" scale="1 1 1"/>
      </geometry>
      <material name="white_blue"/>
    </visual>
    <collision>
      <!-- <xacro:if value="${mirror_dae == True}">
                    <origin rpy="0 0 0" xyz="0 0 0"/>                 
                </xacro:if>
                <xacro:if value="${mirror_dae == False}">
                    <origin rpy="${PI} ${PI} 0" xyz="0 0 0"/>
                </xacro:if> -->
      <origin rpy="0 0 0" xyz="0 0 -0.11"/>
      <geometry>
        <box size="0.043 0.034 0.22"/>
        <!-- <mesh filename="../meshes/thigh.STL" scale="1 1 1"/> -->
      </geometry>
      <material name="white_blue"/>
    </collision>
    <inertial>
      <origin rpy="0 0 0" xyz="0.0 -0.016 -0.11"/>
      <mass value="0.634"/>
      <inertia ixx="0.00261820866667" ixy="0.0" ixz="0.0" iyy="0.00265482216667" iyz="0.0" izz="0.000158764166667"/>
    </inertial>
  </link>
  <!-- //////////////////////calf//////////////////// -->
  <joint name="FL_calf_joint" type="revolute">
    <!-- <joint name="${name}_calf_joint" type="continuous"> -->
    <origin rpy="0 0 0" xyz="0 0.009 -0.2115"/>
    <parent link="FL_thigh"/>
    <child link="FL_calf"/>
    <axis xyz="0 1 0"/>
    <dynamics damping="0" friction="0"/>
    <!-- <limit effort="${calf_torque_max}" velocity="${calf_velocity_max}" lower="${calf_min*PI/180.0}" upper="${calf_max*PI/180.0}"/> -->
    <limit effort="20" lower="-3.14159265359" upper="3.14159265359" velocity="10.6"/>
  </joint>
  <link name="FL_calf">
    <visual>
      <origin rpy="0 0 0" xyz="0.0 0.009 0.0"/>
      <geometry>
        <mesh filename="../meshes/calf.STL" scale="1 1 1"/>
      </geometry>
      <material name="white_blue"/>
    </visual>
    <collision>
      <origin rpy="0 0 0" xyz="0.0 0.0 -0.1"/>
      <geometry>
        <box size="0.016 0.016 0.2"/>
        <!-- <mesh filename="../meshes/calf.STL" scale="1 1 1"/> -->
      </geometry>
    </collision>
    <inertial>
      <origin rpy="0 0 0" xyz="0.0 0.0 0.0"/>
      <mass value="0.064"/>
      <inertia ixx="0.000214698666667" ixy="0.0" ixz="0.0" iyy="0.000214698666667" iyz="0.0" izz="2.73066666667e-06"/>
    </inertial>
  </link>
  <!-- //////////////////////foot//////////////////// -->
  <joint name="FL_foot_fixed" type="fixed">
    <origin rpy="0 0 0" xyz="0 0.01 -0.21"/>
    <parent link="FL_calf"/>
    <child link="FL_foot"/>
  </joint>
  <link name="FL_foot">
    <visual>
      <origin rpy="0 0 0" xyz="0 0.018 0.02"/>
      <geometry>
        <mesh filename="../meshes/foot.STL" scale="1 1 1"/>
      </geometry>
      <material name="white_black"/>
    </visual>
    <collision>
      <origin rpy="0 0 0" xyz="0 0.0 0.025"/>
      <geometry>
        <!-- <mesh filename="../meshes/foot.STL" scale="1 1 1"/> -->
        <sphere radius="0.025"/>
      </geometry>
    </collision>
    <inertial>
      <origin rpy="0 0 0" xyz="0.0 0.0 0"/>
      <mass value="0.15"/>
      <inertia ixx="4.2135e-05" ixy="0.0" ixz="0.0" iyy="4.2135e-05" iyz="0.0" izz="4.2135e-05"/>
    </inertial>
  </link>

  <!-- //////////////////////hip//////////////////// -->
  <joint name="RR_hip_joint" type="revolute">
    <!-- <joint name="${name}_hip_joint" type="continuous"> -->
    <origin rpy="3.14159265359 0 0" xyz="-0.196 -0.049664 0"/>
    <parent link="trunk"/>
    <child link="RR_hip"/>
    <axis xyz="1 0 0"/>
    <dynamics damping="0" friction="0"/>
    <limit effort="20" lower="-1.0471975512" upper="0.872664625997" velocity="10.6"/>
  </joint>
  <link name="RR_hip">
    <visual>
      <origin rpy="0 0 0" xyz="0 0 0"/>
      <geometry>
        <mesh filename="../meshes/hip.STL" scale="1 1 1"/>
      </geometry>
      <material name="gold"/>
    </visual>
    <collision>
      <!-- <origin rpy="${PI/2.0} 0 0" xyz="0 0 0"/> -->
      <!-- <xacro:if value="${(mirror_dae == True) and (front_hind_dae == True)}">
                    <origin rpy="0 0 0" xyz="0 0 0"/>
                </xacro:if>
                <xacro:if value="${(mirror_dae == False) and (front_hind_dae == True)}">
                    <origin rpy="${PI} 0 0" xyz="0 0 0"/>
                </xacro:if>
                <xacro:if value="${(mirror_dae == True) and (front_hind_dae == False)}">
                    <origin rpy="0 ${PI} 0" xyz="0 0 0"/>
                </xacro:if>
                <xacro:if value="${(mirror_dae == False) and (front_hind_dae == False)}">
                    <origin rpy="${PI} ${PI} 0" xyz="0 0 0"/>
                </xacro:if> -->
      <geometry>
        <!-- <mesh filename="../meshes/hip.STL" scale="1 1 1"/> -->
        <box size="0.09 0.08 0.093"/>
      </geometry>
    </collision>
    <inertial>
      <origin rpy="0 0 0" xyz="0.0 0.036 0.0"/>
      <mass value="0.57"/>
      <inertia ixx="0.0007148275" ixy="0.0" ixz="0.0" iyy="0.0007955775" iyz="0.0" izz="0.00068875"/>
    </inertial>
  </link>
  <!-- //////////////////////thigh//////////////////// -->
  <joint name="RR_thigh_joint" type="revolute">
    <!-- <joint name="${name}_thigh_joint" type="continuous"> -->
    <origin rpy="3.14159265359 0 0" xyz="0 0.077476 0"/>
    <parent link="RR_hip"/>
    <child link="RR_thigh"/>
    <axis xyz="0 1 0"/>
    <dynamics damping="0" friction="0"/>
    <limit effort="20" lower="-0.523598775598" upper="3.92699081699" velocity="10.6"/>
  </joint>
  <link name="RR_thigh">
    <visual>
      <origin rpy="0 0 0" xyz="0 0 0"/>
      <geometry>
        <mesh filename="../meshes/thigh.STL" scale="1 1 1"/>
      </geometry>
      <material name="white_blue"/>
    </visual>
    <collision>
      <!-- <xacro:if value="${mirror_dae == True}">
                    <origin rpy="0 0 0" xyz="0 0 0"/>                 
                </xacro:if>
                <xacro:if value="${mirror_dae == False}">
                    <origin rpy="${PI} ${PI} 0" xyz="0 0 0"/>
                </xacro:if> -->
      <origin rpy="0 0 0" xyz="0 0 -0.11"/>
      <geometry>
        <box size="0.043 0.034 0.22"/>
        <!-- <mesh filename="../meshes/thigh.STL" scale="1 1 1"/> -->
      </geometry>
      <material name="white_blue"/>
    </collision>
    <inertial>
      <origin rpy="0 0 0" xyz="0.0 0.016 -0.11"/>
      <mass value="0.634"/>
      <inertia ixx="0.00261820866667" ixy="0.0" ixz="0.0" iyy="0.00265482216667" iyz="0.0" izz="0.000158764166667"/>
    </inertial>
  </link>
  <!-- //////////////////////calf//////////////////// -->
  <joint name="RR_calf_joint" type="revolute">
    <!-- <joint name="${name}_calf_joint" type="continuous"> -->
    <origin rpy="0 0 0" xyz="0 0.009 -0.2115"/>
    <parent link="RR_thigh"/>
    <child link="RR_calf"/>
    <axis xyz="0 1 0"/>
    <dynamics damping="0" friction="0"/>
    <!-- <limit effort="${calf_torque_max}" velocity="${calf_velocity_max}" lower="${calf_min*PI/180.0}" upper="${calf_max*PI/180.0}"/> -->
    <limit effort="20" lower="-3.14159265359" upper="3.14159265359" velocity="10.6"/>
  </joint>
  <link name="RR_calf">
    <visual>
      <origin rpy="0 0 0" xyz="0.0 0.009 0.0"/>
      <geometry>
        <mesh filename="../meshes/calf.STL" scale="1 1 1"/>
      </geometry>
      <material name="white_blue"/>
    </visual>
    <collision>
      <origin rpy="0 0 0" xyz="0.0 0.0 -0.1"/>
      <geometry>
        <box size="0.016 0.016 0.2"/>
        <!-- <mesh filename="../meshes/calf.STL" scale="1 1 1"/> -->
      </geometry>
    </collision>
    <inertial>
      <origin rpy="0 0 0" xyz="0.0 0.0 0.0"/>
      <mass value="0.064"/>
      <inertia ixx="0.000214698666667" ixy="0.0" ixz="0.0" iyy="0.000214698666667" iyz="0.0" izz="2.73066666667e-06"/>
    </inertial>
  </link>
  <!-- //////////////////////foot//////////////////// -->
  <joint name="RR_foot_fixed" type="fixed">
    <origin rpy="0 0 0" xyz="0 0.01 -0.21"/>
    <parent link="RR_calf"/>
    <child link="RR_foot"/>
  </joint>
  <link name="RR_foot">
    <visual>
      <origin rpy="0 0 0" xyz="0 0.018 0.02"/>
      <geometry>
        <mesh filename="../meshes/foot.STL" scale="1 1 1"/>
      </geometry>
      <material name="white_black"/>
    </visual>
    <collision>
      <origin rpy="0 0 0" xyz="0 0.0 0.025"/>
      <geometry>
        <!-- <mesh filename="../meshes/foot.STL" scale="1 1 1"/> -->
        <sphere radius="0.025"/>
      </geometry>
    </collision>
    <inertial>
      <origin rpy="0 0 0" xyz="0.0 0.0 0"/>
      <mass value="0.15"/>
      <inertia ixx="4.2135e-05" ixy="0.0" ixz="0.0" iyy="4.2135e-05" iyz="0.0" izz="4.2135e-05"/>
    </inertial>
  </link>

  <!-- //////////////////////hip//////////////////// -->
  <joint name="FR_hip_joint" type="revolute">
    <!-- <joint name="${name}_hip_joint" type="continuous"> -->
    <origin rpy="3.14159265359 3.14159265359 0" xyz="0.196 -0.049664 0"/>
    <parent link="trunk"/>
    <child link="FR_hip"/>
    <axis xyz="1 0 0"/>
    <dynamics damping="0" friction="0"/>
    <limit effort="20" lower="-1.0471975512" upper="0.872664625997" velocity="10.6"/>
  </joint>
  <link name="FR_hip">
    <visual>
      <origin rpy="0 3.14159265359 0" xyz="0 0 0"/>
      <geometry>
        <mesh filename="../meshes/hip.STL" scale="1 1 1"/>
      </geometry>
      <material name="gold"/>
    </visual>
    <collision>

      <geometry>
        <!-- <mesh filename="../meshes/hip.STL" scale="1 1 1"/> -->
        <box size="0.09 0.08 0.093"/>
      </geometry>
    </collision>
    <inertial>
      <origin rpy="0 0 0" xyz="-0.0 0.036 0.0"/>
      <mass value="0.57"/>
      <inertia ixx="0.0007148275" ixy="0.0" ixz="0.0" iyy="0.0007955775" iyz="0.0" izz="0.00068875"/>
    </inertial>
  </link>
  <!-- //////////////////////thigh//////////////////// -->
  <joint name="FR_thigh_joint" type="revolute">
    <!-- <joint name="${name}_thigh_joint" type="continuous"> -->
    <origin rpy="3.14159265359 3.14159265359 0" xyz="0 0.077476 0"/>
    <parent link="FR_hip"/>
    <child link="FR_thigh"/>
    <axis xyz="0 1 0"/>
    <dynamics damping="0" friction="0"/>
    <limit effort="20" lower="-0.523598775598" upper="3.92699081699" velocity="10.6"/>
  </joint>
  <link name="FR_thigh">
    <visual>
      <origin rpy="0 0 0" xyz="0 0 0"/>
      <geometry>
        <mesh filename="../meshes/thigh.STL" scale="1 1 1"/>
      </geometry>
      <material name="white_blue"/>
    </visual>
    <collision>
      <!-- <xacro:if value="${mirror_dae == True}">
                    <origin rpy="0 0 0" xyz="0 0 0"/>                 
                </xacro:if>
                <xacro:if value="${mirror_dae == False}">
                    <origin rpy="${PI} ${PI} 0" xyz="0 0 0"/>
                </xacro:if> -->
      <origin rpy="0 0 0" xyz="0 0 -0.11"/>
      <geometry>
        <box size="0.043 0.034 0.22"/>
        <!-- <mesh filename="../meshes/thigh.STL" scale="1 1 1"/> -->
      </geometry>
      <material name="white_blue"/>
    </collision>
    <inertial>
      <origin rpy="0 0 0" xyz="0.0 0.016 -0.11"/>
      <mass value="0.634"/>
      <inertia ixx="0.00261820866667" ixy="0.0" ixz="0.0" iyy="0.00265482216667" iyz="0.0" izz="0.000158764166667"/>
    </inertial>
  </link>
  <!-- //////////////////////calf//////////////////// -->
  <joint name="FR_calf_joint" type="revolute">
    <!-- <joint name="${name}_calf_joint" type="continuous"> -->
    <origin rpy="0 0 0" xyz="0 0.009 -0.2115"/>
    <parent link="FR_thigh"/>
    <child link="FR_calf"/>
    <axis xyz="0 1 0"/>
    <dynamics damping="0" friction="0"/>
    <!-- <limit effort="${calf_torque_max}" velocity="${calf_velocity_max}" lower="${calf_min*PI/180.0}" upper="${calf_max*PI/180.0}"/> -->
    <limit effort="20" lower="-3.14159265359" upper="3.14159265359" velocity="10.6"/>
  </joint>
  <link name="FR_calf">
    <visual>
      <origin rpy="0 0 0" xyz="0.0 0.009 0.0"/>
      <geometry>
        <mesh filename="../meshes/calf.STL" scale="1 1 1"/>
      </geometry>
      <material name="white_blue"/>
    </visual>
    <collision>
      <origin rpy="0 0 0" xyz="0.0 0.0 -0.1"/>
      <geometry>
        <box size="0.016 0.016 0.2"/>
        <!-- <mesh filename="../meshes/calf.STL" scale="1 1 1"/> -->
      </geometry>
    </collision>
    <inertial>
      <origin rpy="0 0 0" xyz="0.0 0.0 0.0"/>
      <mass value="0.064"/>
      <inertia ixx="0.000214698666667" ixy="0.0" ixz="0.0" iyy="0.000214698666667" iyz="0.0" izz="2.73066666667e-06"/>
    </inertial>
  </link>
  <!-- //////////////////////foot//////////////////// -->
  <joint name="FR_foot_fixed" type="fixed">
    <origin rpy="0 0 0" xyz="0 0.01 -0.21"/>
    <parent link="FR_calf"/>
    <child link="FR_foot"/>
  </joint>
  <link name="FR_foot">
    <visual>
      <origin rpy="0 0 0" xyz="0 0.018 0.02"/>
      <geometry>
        <mesh filename="../meshes/foot.STL" scale="1 1 1"/>
      </geometry>
      <material name="white_black"/>
    </visual>
    <collision>
      <origin rpy="0 0 0" xyz="0 0.0 0.025"/>
      <geometry>
        <!-- <mesh filename="../meshes/foot.STL" scale="1 1 1"/> -->
        <sphere radius="0.025"/>
      </geometry>
    </collision>
    <inertial>
      <origin rpy="0 0 0" xyz="0.0 0.0 0"/>
      <mass value="0.15"/>
      <inertia ixx="4.2135e-05" ixy="0.0" ixz="0.0" iyy="4.2135e-05" iyz="0.0" izz="4.2135e-05"/>
    </inertial>
  </link>


</robot>

